{"nbformat":4,"nbformat_minor":0,"metadata":{"colab":{"provenance":[],"authorship_tag":"ABX9TyMihe3zVtT1sqtAA6Jej54U"},"kernelspec":{"name":"python3","display_name":"Python 3"},"language_info":{"name":"python"}},"cells":[{"cell_type":"markdown","source":["# Class 6: Error Handling and Exceptions"],"metadata":{"id":"2YToChZtZp25"}},{"cell_type":"markdown","source":["Welcome to the sixth class of our Python course! Today, we'll dive into error handling and exceptions in Python. Understanding how to handle errors effectively is crucial for writing robust and error-resistant code. Let's get started!"],"metadata":{"id":"VcJMsol4aGfm"}},{"cell_type":"markdown","source":["## 1. Error Types"],"metadata":{"id":"xxp1J9S4aHjk"}},{"cell_type":"markdown","source":["Errors are inevitable when writing code, but understanding the types of errors and how to handle them can make your programs more resilient."],"metadata":{"id":"GrcenisdaRVX"}},{"cell_type":"markdown","source":["### 1.1. Syntax Errors"],"metadata":{"id":"LieFWW8DVvIP"}},{"cell_type":"markdown","source":["**Syntax errors** occur when the Python interpreter encounters code that doesn't conform to the syntax rules of the language. These errors are usually detected when the code is parsed, before it runs."],"metadata":{"id":"154W9VkgVxpC"}},{"cell_type":"code","source":["# Syntax Error Example\n","print(\"Hello, world!\"  # Missing closing parenthesis"],"metadata":{"id":"D97SvQ4DhsD_"},"execution_count":null,"outputs":[]},{"cell_type":"markdown","source":["### 1.2. Runtime Errors"],"metadata":{"id":"I9NoEm25iL7P"}},{"cell_type":"markdown","source":["Runtime errors occur while the program is running. These errors happen when the code is syntactically correct but fails to execute due to some issue."],"metadata":{"id":"vRvkOJpJiOMC"}},{"cell_type":"code","source":["# Runtime Error Example\n","result = 10 / 0  # Division by zero raises a ZeroDivisionError"],"metadata":{"id":"VO_1GGeBiZ9z"},"execution_count":null,"outputs":[]},{"cell_type":"markdown","source":["### 1.3. Logical Errors"],"metadata":{"id":"ryCEZjQAicFb"}},{"cell_type":"markdown","source":["Logical errors occur when the program runs without crashing but produces incorrect results. These errors are often the most challenging to detect because the code appears to work but doesn't do what you expect."],"metadata":{"id":"BDmWRUR8id4S"}},{"cell_type":"code","source":["# Logical Error Example\n","def calculate_area(radius):\n","    return 3.14 * radius * radius  # Correct formula is area = Ï€ * r^2\n","\n","# Using the function with radius 2\n","area = calculate_area(2)\n","print(area)  # This might be correct, but if the formula was wrong, the result would be wrong too"],"metadata":{"id":"5vXzrHKHifad"},"execution_count":null,"outputs":[]},{"cell_type":"markdown","source":["## 2. Exception Handling"],"metadata":{"id":"HyCuCRD8ij4N"}},{"cell_type":"markdown","source":["Exceptions are events that disrupt the normal flow of a program's execution. In Python, exceptions can be handled using `try`, `except`, `finally`, and `else` blocks."],"metadata":{"id":"7b3c_JlWiyxf"}},{"cell_type":"markdown","source":["### 2.1. Using `try`, `except` Blocks"],"metadata":{"id":"oN0vAD7rjbbe"}},{"cell_type":"markdown","source":["The `try` block lets you test a block of code for errors. The `except` block lets you handle the error."],"metadata":{"id":"OzgHhvpajdqv"}},{"cell_type":"markdown","source":["Syntax:"],"metadata":{"id":"GcJQ0_fNnpaW"}},{"cell_type":"code","source":["try:\n","    # Code that might raise an exception\n","    pass\n","except ExceptionType:\n","    # Code that runs if the exception occurs\n","    pass"],"metadata":{"id":"CF007EzMniri"},"execution_count":null,"outputs":[]},{"cell_type":"markdown","source":["Example:"],"metadata":{"id":"a1yKylXnnrHY"}},{"cell_type":"code","source":["# Example of try-except block\n","try:\n","    result = 10 / 0\n","except ZeroDivisionError:\n","    print(\"Cannot divide by zero!\")"],"metadata":{"id":"Mfc4D5uonsQv"},"execution_count":null,"outputs":[]},{"cell_type":"markdown","source":["### 2.2. Multiple Exceptions"],"metadata":{"id":"I-3IKWfBn3h0"}},{"cell_type":"markdown","source":["You can handle multiple exceptions by specifying different except blocks for different exception types."],"metadata":{"id":"YpmR0Oo1n7Kh"}},{"cell_type":"code","source":["# Handling multiple exceptions\n","try:\n","    number = int(input(\"Enter a number: \"))\n","    result = 10 / number\n","except ValueError:\n","    print(\"That's not a valid number!\")\n","except ZeroDivisionError:\n","    print(\"Cannot divide by zero!\")"],"metadata":{"id":"Cv7AKSMJn82R"},"execution_count":null,"outputs":[]},{"cell_type":"markdown","source":["### 2.3. `finally` and `else` Clauses"],"metadata":{"id":"TYX0X0pVn-wO"}},{"cell_type":"markdown","source":["* The `finally` block is always executed, regardless of whether an exception was\n","raised or not. It's often used to clean up resources like closing files or releasing connections.\n","* The `else` block is executed if no exceptions were raised in the try block."],"metadata":{"id":"SMlPTHgBoHG1"}},{"cell_type":"code","source":["# Example with finally and else\n","try:\n","    file = open(\"example.txt\", \"r\")\n","    content = file.read()\n","except FileNotFoundError:\n","    print(\"File not found!\")\n","else:\n","    print(\"File read successfully.\")\n","finally:\n","    file.close()\n","    print(\"File closed.\")"],"metadata":{"id":"r4zDxze1oVSi"},"execution_count":null,"outputs":[]},{"cell_type":"markdown","source":["## 3. Common Exceptions in Python"],"metadata":{"id":"FGQhZppcolwC"}},{"cell_type":"markdown","source":["Here are some common exceptions you might encounter:\n","\n","* `ValueError`: Raised when a function receives an argument of the right type but an inappropriate value.\n","* `TypeError`: Raised when an operation or function is applied to an object of inappropriate type.\n","* `IndexError`: Raised when trying to access an index that is out of range in a sequence.\n","* `KeyError`: Raised when trying to access a dictionary key that doesn't exist.\n","* `FileNotFoundError`: Raised when trying to open a file that doesn't exist."],"metadata":{"id":"tu209XaRonzT"}},{"cell_type":"code","source":["try:\n","    numbers = [1, 2, 3]\n","    print(numbers[5])  # IndexError\n","except IndexError as e:\n","    print(f\"Error occurred: {e}\")"],"metadata":{"id":"vYqqjB_bo5Tx"},"execution_count":null,"outputs":[]},{"cell_type":"markdown","source":["## 4. Example: Handling Multiple Exceptions"],"metadata":{"id":"K40qdIlyo9d0"}},{"cell_type":"markdown","source":["Let's create a practical example where we handle multiple exceptions in a single piece of code."],"metadata":{"id":"lSoWRH8NpAf2"}},{"cell_type":"code","source":["# Example of handling multiple exceptions\n","def divide_numbers():\n","    try:\n","        numerator = int(input(\"Enter the numerator: \"))\n","        denominator = int(input(\"Enter the denominator: \"))\n","        result = numerator / denominator\n","    except ValueError:\n","        print(\"Both inputs must be numbers!\")\n","    except ZeroDivisionError:\n","        print(\"The denominator cannot be zero!\")\n","    else:\n","        print(f\"The result is {result}\")\n","    finally:\n","        print(\"Execution completed.\")\n","\n","divide_numbers()"],"metadata":{"id":"VT3jM8QYpDHM"},"execution_count":null,"outputs":[]},{"cell_type":"markdown","source":["## 5. Exercises"],"metadata":{"id":"MJuuSivJpHL7"}},{"cell_type":"markdown","source":["Now it's time to practice what you've learned! Try to solve the following exercises."],"metadata":{"id":"cc-w86aUpI-P"}},{"cell_type":"markdown","source":["### Exercise 1: Basic Exception Handling"],"metadata":{"id":"NuF5HL_ppKUY"}},{"cell_type":"markdown","source":["Write a program that asks the user to enter a number and then tries to convert it to an integer. If the conversion fails, catch the exception and print an error message."],"metadata":{"id":"cYZdBZIrpLf1"}},{"cell_type":"markdown","source":["### Exercise 2: Handling Multiple Exceptions"],"metadata":{"id":"Z5cMwF_WpOfY"}},{"cell_type":"markdown","source":["Write a program that prompts the user to enter two numbers and then divides the first by the second. Handle exceptions for invalid input and division by zero."],"metadata":{"id":"rwrsnkPipQ1P"}},{"cell_type":"markdown","source":["### Exercise 3: Using `finally`"],"metadata":{"id":"zVe_MBK2pSAD"}},{"cell_type":"markdown","source":["Write a program that opens a file, reads its content, and prints it to the screen. Ensure that the file is closed after the operation, whether an exception occurs or not."],"metadata":{"id":"0hi7Kgr-pXGP"}},{"cell_type":"markdown","source":["### Exercise 4: Custom Exceptions"],"metadata":{"id":"lbX4tNmUpYWx"}},{"cell_type":"markdown","source":["Create a custom exception class called NegativeNumberError. Write a program that asks the user to enter a positive number. If the user enters a negative number, raise the NegativeNumberError and handle it appropriately."],"metadata":{"id":"ArFUpF4JpaB-"}},{"cell_type":"markdown","source":["Feel free to experiment and explore different error handling techniques. Understanding and handling exceptions is a critical part of writing robust Python code. Happy coding!"],"metadata":{"id":"ni1EGoLjpbaS"}}]}